Workbook

Sheet README
A1: Apple Inc. (AAPL) — 3-Statement Financial Model & Forecast
A2: Built on real FY2023–FY2025 SEC filings (10-K / 8-K) | Forecast: FY2026E–FY2028E
A5: PURPOSE
A6: This model replicates the core day-to-day deliverable of an FP&A analyst: a fully-linked three-statement
A7: model (Income Statement, Balance Sheet, Cash Flow Statement) built from a public company's actual
A8: financial filings, with a driver-based forecast and a built-in 'what if revenue drops 10%' scenario test.
A10: HOW THIS MODEL IS BUILT
A11: - FY2023A-FY2025A columns are HARD-CODED ACTUALS sourced directly from Apple's 10-K and 8-K filings on
A12: SEC EDGAR (cell comments show the exact source). Blue font = hardcoded input.
A13: - FY2026E-FY2028E columns are 100% FORMULA-DRIVEN from the Assumptions tab. Change any blue assumption
A14: cell and the entire model (IS, BS, CFS, EPS) recalculates automatically.
A15: - The Balance Sheet includes a 'Balance Check' row that must equal zero in every period — this confirms
... A48: Author: Karis Fang | Portfolio project for FP&A roles | github.com/karisfang

Sheet Assumptions
A1: Key Assumptions & Scenario Selector
A2: Blue = hardcoded input you can change. Everything downstream recalculates automatically.
A4: Scenario Selector | B4: Base | C4: <- choose scenario here
A6: REVENUE GROWTH ASSUMPTIONS (by scenario)
E7: FY2026E | F7: FY2027E | G7: FY2028E
A8: Base Case Revenue Growth % | E8: 0.08 | F8: 0.07 | G8: 0.07
A9: Bear Case Growth % (FY26E shock; FY27E/28E recover to Base) | E9: -0.1
A10: Bull Case Growth % (FY26E upside; FY27E/28E = Base) | E10: 0.12
A11: Active Revenue Growth % (driven by Scenario Selector) | E11: =IF($B$4="Bear (-10% Rev Shock)",$E$9,IF($B$4="Bull (Upside)",$E$10,$E$8)) -> 0.08 | F11: =$F$8 -> 0.07 | G11: =$G$8 -> 0.07
A13: MARGIN & OPERATING EXPENSE ASSUMPTIONS
E14: FY2026E | F14: FY2027E | G14: FY2028E
A15: Gross Margin % | E15: 0.472 | F15: 0.475 | G15: 0.477
A16: R&D % of Net Sales | E16: 0.082 | F16: 0.082 | G16: 0.082
A17: SG&A % of Net Sales | E17: 0.066 | F17: 0.066 | G17: 0.066
A18: Other Income/(Expense) % of Net Sales | E18: -0.001 | F18: -0.001 | G18: -0.001
A19: Effective Tax Rate % | E19: 0.16 | F19: 0.16 | G19: 0.16 | H19: FY24A rate (24.1%) excludes one-time EU State Aid tax charge; FY23A/FY25A ~15-16% used as normalized basis
A21: WORKING CAPITAL & BALANCE SHEET DRIVERS (fixed across forecast & scenarios)
A22: Days Sales Outstanding - Accounts Receivable | B22: 33
A23: Days Inventory Outstanding | B23: 9
A24: Days Payable Outstanding - Accounts Payable | B24: 113
A25: Vendor Non-Trade Receivables % of Net Sales | B25: 0.08
A26: Other Current Assets % of Net Sales | B26: 0.035
A27: Other Non-Current Assets % of Net Sales | B27: 0.2
A28: Other Current Liabilities % of Net Sales | B28: 0.16
A29: Deferred Revenue % of Net Sales | B29: 0.022
A30: Other Non-Current Liabilities % of Net Sales | B30: 0.1
A32: CAPEX, D&A & CAPITAL RETURN ASSUMPTIONS
E33: FY2026E | F33: FY2027E | G33: FY2028E
A34: Capex % of Net Sales | E34: 0.03 | F34: 0.03 | G34: 0.03
A35: D&A % of Net Sales | E35: 0.028 | F35: 0.028 | G35: 0.028
A36: Stock-Based Compensation % of Net Sales | E36: 0.03 | F36: 0.03 | G36: 0.03
A37: Tax Withholding on Equity Awards (% of SBC) | E37: 0.45 | F37: 0.45 | G37: 0.45
A38: Dividend Growth Rate % (YoY) | B38: 0.04
A39: Buyback Payout Ratio (% of Free Cash Flow) | B39: 0.75
A40: Average Share Price Assumption ($, for buyback share count) | E40: 240 | F40: 255 | G40: 270

Sheet Income Statement
A1: Apple Inc. — Consolidated Income Statement ($ in millions, except per-share)
A2: FY2023A-FY2025A: actuals from 10-K/8-K filings | FY2026E-FY2028E: driven by Assumptions tab
B4: FY2023A | C4: FY2024A | D4: FY2025A | E4: FY2026E | F4: FY2027E | G4: FY2028E
A5: Net Sales:
A6: Products | B6: 298085 | C6: 294866 | D6: 307003
A7: Services | B7: 85200 | C7: 96169 | D7: 109158
A8: Total Net Sales | B8: 383285 | C8: 391035 | D8: 416161 | E8: =D8*(1+Assumptions!E11) -> 449453.88 | F8: =E8*(1+Assumptions!F11) -> 480915.65 | G8: =F8*(1+Assumptions!G11) -> 514579.75
A10: Cost of Sales:
A11: Products | B11: 189282 | C11: 185233 | D11: 194116
A12: Services | B12: 24855 | C12: 25119 | D12: 26844
A13: Total Cost of Sales | B13: 214137 | C13: 210352 | D13: 220960 | E13: =E8-E14 -> 237311.65 | F13: =F8-F14 -> 252480.72 | G13: =G8-G14 -> 269125.21
A14: Gross Margin | B14: =B8-B13 -> 169148 | C14: =C8-C13 -> 180683 | D14: =D8-D13 -> 195201 | E14: =E8*Assumptions!E15 -> 212142.23 | F14: =F8*Assumptions!F15 -> 228434.93 | G14: =G8*Assumptions!G15 -> 245454.54
A15: Gross Margin % | B15: =B14/B8 -> 0.4413113 | C15: =C14/C8 -> 0.4620635 | D15: =D14/D8 -> 0.46905164 | E15: =E14/E8 -> 0.472 | F15: =F14/F8 -> 0.475 | G15: =G14/G8 -> 0.477
A17: Operating Expenses:
A18: Research and Development | B18: 29915 | C18: 31370 | D18: 34550 | E18: =E8*Assumptions!E16 -> 36855.218 | F18: =F8*Assumptions!F16 -> 39435.083 | G18: =G8*Assumptions!G16 -> 42195.539
A19: Selling, General and Administrative | B19: 24932 | C19: 26097 | D19: 27601 | E19: =E8*Assumptions!E17 -> 29663.956 | F19: =F8*Assumptions!F17 -> 31740.433 | G19: =G8*Assumptions!G17 -> 33962.263
A20: Total Operating Expenses | B20: =SUM(B18:B19) -> 54847 | C20: =SUM(C18:C19) -> 57467 | D20: =SUM(D18:D19) -> 62151 | E20: =SUM(E18:E19) -> 66519.174 | F20: =SUM(F18:F19) -> 71175.516 | G20: =SUM(G18:G19) -> 76157.803
A22: Operating Income | B22: =B14-B20 -> 114301 | C22: =C14-C20 -> 123216 | D22: =D14-D20 -> 133050 | E22: =E14-E20 -> 145623.06 | F22: =F14-F20 -> 157259.42 | G22: =G14-G20 -> 169296.74
A23: Operating Margin % | B23: =B22/B8 -> 0.29821412 | C23: =C22/C8 -> 0.31510223 | D23: =D22/D8 -> 0.319708 | E23: =E22/E8 -> 0.324 | F23: =F22/F8 -> 0.327 | G23: =G22/G8 -> 0.329
A25: Other Income/(Expense), net | B25: -565 | C25: 269 | D25: -321 | E25: =E8*Assumptions!E18 -> -449.45388 | F25: =F8*Assumptions!F18 -> -480.91565 | G25: =G8*Assumptions!G18 -> -514.57975
A26: Income Before Provision for Income Taxes | B26: =B22+B25 -> 113736 | C26: =C22+C25 -> 123485 | D26: =D22+D25 -> 132729 | E26: =E22+E25 -> 145173.6 | F26: =F22+F25 -> 156778.5 | G26: =G22+G25 -> 168782.16
A27: Provision for Income Taxes | B27: 16741 | C27: 29749 | D27: 20719 | E27: =E26*Assumptions!E19 -> 23227.777 | F27: =F26*Assumptions!F19 -> 25084.56 | G27: =G26*Assumptions!G19 -> 27005.145
A28: Net Income | B28: =B26-B27 -> 96995 | C28: =C26-C27 -> 93736 | D28: =D26-D27 -> 112010 | E28: =E26-E27 -> 121945.83 | F28: =F26-F27 -> 131693.94 | G28: =G26-G27 -> 141777.01
A29: Net Margin % | B29: =B28/B8 -> 0.25306234 | C29: =C28/C8 -> 0.23971256 | D29: =D28/D8 -> 0.26915064 | E29: =E28/E8 -> 0.27132 | F29: =F28/F8 -> 0.27384 | G29: =G28/G8 -> 0.27552
A31: Diluted Shares Outstanding (000s) | B31: 15812547 | C31: 15408095 | D31: 15004697 | E31: =D31+'Cash Flow Statement'!E29/Assumptions!E40*1000 -> 14577145 | F31: =E31+'Cash Flow Statement'!F29/Assumptions!F40*1000 -> 14148913 | G31: =F31+'Cash Flow Statement'!G29/Assumptions!G40*1000 -> 13713432
A32: Diluted EPS | B32: =B28*1000/B31 -> 6.1340529 | C32: =C28*1000/C31 -> 6.0835554 | D32: =D28*1000/D31 -> 7.4649958 | E32: =E28*1000/E31 -> 8.3655493 | F32: =F28*1000/F31 -> 9.3077075 | G32: =G28*1000/G31 -> 10.338551

Sheet Balance Sheet
A1: Apple Inc. — Consolidated Balance Sheet ($ in millions)
A2: FY2023A-FY2025A: actuals from 10-K/8-K filings | FY2026E-FY2028E: driven by Assumptions tab
B4: FY2023A | C4: FY2024A | D4: FY2025A | E4: FY2026E | F4: FY2027E | G4: FY2028E
A5: ASSETS
A6: Current Assets:
A7: Cash and Cash Equivalents | B7: 29965 | C7: 29943 | D7: 35934 | E7: =D7+'Cash Flow Statement'!E34 -> 48032.674 | F7: =E7+'Cash Flow Statement'!F34 -> 61260.709 | G7: =F7+'Cash Flow Statement'!G34 -> 76160.671
A8: Marketable Securities (Current) | B8: 31590 | C8: 35228 | D8: 18763 | E8: =D8 -> 18763 | F8: =E8 -> 18763 | G8: =F8 -> 18763
A9: Accounts Receivable, net | B9: 29508 | C9: 33410 | D9: 39777 | E9: ='Income Statement'!E8/365*Assumptions!$B$22 -> 40635.556 | F9: ='Income Statement'!F8/365*Assumptions!$B$22 -> 43480.045 | G9: ='Income Statement'!G8/365*Assumptions!$B$22 -> 46523.648
A10: Vendor Non-Trade Receivables | B10: 31477 | C10: 32833 | D10: 33180 | E10: ='Income Statement'!E8*Assumptions!$B$25 -> 35956.31 | F10: ='Income Statement'!F8*Assumptions!$B$25 -> 38473.252 | G10: ='Income Statement'!G8*Assumptions!$B$25 -> 41166.38
A11: Inventories | B11: 6331 | C11: 7286 | D11: 5718 | E11: ='Income Statement'!E13/365*Assumptions!$B$23 -> 5851.5201 | F11: ='Income Statement'!F13/365*Assumptions!$B$23 -> 6225.5519 | G11: ='Income Statement'!G13/365*Assumptions!$B$23 -> 6635.964
A12: Other Current Assets | B12: 14695 | C12: 14287 | D12: 14585 | E12: ='Income Statement'!E8*Assumptions!$B$26 -> 15730.886 | F12: ='Income Statement'!F8*Assumptions!$B$26 -> 16832.048 | G12: ='Income Statement'!G8*Assumptions!$B$26 -> 18010.291
A13: Total Current Assets | B13: =SUM(B7:B12) -> 143566 | C13: =SUM(C7:C12) -> 152987 | D13: =SUM(D7:D12) -> 147957 | E13: =SUM(E7:E12) -> 164969.95 | F13: =SUM(F7:F12) -> 185034.61 | G13: =SUM(G7:G12) -> 207259.95
A15: Non-Current Assets:
A16: Marketable Securities (Non-Current) | B16: 100544 | C16: 91479 | D16: 77723 | E16: =D16 -> 77723 | F16: =E16 -> 77723 | G16: =F16 -> 77723
A17: Property, Plant and Equipment, net | B17: 43715 | C17: 45680 | D17: 49834 | E17: =D17-'Cash Flow Statement'!E23-'Cash Flow Statement'!E7 -> 50732.908 | F17: =E17-'Cash Flow Statement'!F23-'Cash Flow Statement'!F7 -> 51694.739 | G17: =F17-'Cash Flow Statement'!G23-'Cash Flow Statement'!G7 -> 52723.899
A18: Other Non-Current Assets | B18: 64758 | C18: 74834 | D18: 83727 | E18: ='Income Statement'!E8*Assumptions!$B$27 -> 89890.776 | F18: ='Income Statement'!F8*Assumptions!$B$27 -> 96183.13 | G18: ='Income Statement'!G8*Assumptions!$B$27 -> 102915.95
A19: Total Non-Current Assets | B19: =SUM(B16:B18) -> 209017 | C19: =SUM(C16:C18) -> 211993 | D19: =SUM(D16:D18) -> 211284 | E19: =SUM(E16:E18) -> 218346.68 | F19: =SUM(F16:F18) -> 225600.87 | G19: =SUM(G16:G18) -> 233362.85
A20: TOTAL ASSETS | B20: =B13+B19 -> 352583 | C20: =C13+C19 -> 364980 | D20: =D13+D19 -> 359241 | E20: =E13+E19 -> 383316.63 | F20: =F13+F19 -> 410635.48 | G20: =G13+G19 -> 440622.8
A22: LIABILITIES AND SHAREHOLDERS' EQUITY
A23: Current Liabilities:
A24: Accounts Payable | B24: 62611 | C24: 68960 | D24: 69860 | E24: ='Income Statement'!E13/365*Assumptions!$B$24 -> 73469.086 | F24: ='Income Statement'!F13/365*Assumptions!$B$24 -> 78165.263 | G24: ='Income Statement'!G13/365*Assumptions!$B$24 -> 83318.215
A25: Other Current Liabilities | B25: 58829 | C25: 78304 | D25: 66387 | E25: ='Income Statement'!E8*Assumptions!$B$28 -> 71912.621 | F25: ='Income Statement'!F8*Assumptions!$B$28 -> 76946.504 | G25: ='Income Statement'!G8*Assumptions!$B$28 -> 82332.76
A26: Deferred Revenue | B26: 8061 | C26: 8249 | D26: 9055 | E26: ='Income Statement'!E8*Assumptions!$B$29 -> 9887.9854 | F26: ='Income Statement'!F8*Assumptions!$B$29 -> 10580.144 | G26: ='Income Statement'!G8*Assumptions!$B$29 -> 11320.754
A27: Commercial Paper | B27: 5985 | C27: 9967 | D27: 7979 | E27: =D27 -> 7979 | F27: =E27 -> 7979 | G27: =F27 -> 7979
A28: Term Debt (Current Portion) | B28: 9822 | C28: 10912 | D28: 12350 | E28: =D28 -> 12350 | F28: =E28 -> 12350 | G28: =F28 -> 12350
A29: Total Current Liabilities | B29: =SUM(B24:B28) -> 145308 | C29: =SUM(C24:C28) -> 176392 | D29: =SUM(D24:D28) -> 165631 | E29: =SUM(E24:E28) -> 175598.69 | F29: =SUM(F24:F28) -> 186020.91 | G29: =SUM(G24:G28) -> 197300.73
A31: Non-Current Liabilities:
A32: Term Debt (Non-Current) | B32: 95281 | C32: 85750 | D32: 78328 | E32: =D32 -> 78328 | F32: =E32 -> 78328 | G32: =F32 -> 78328
A33: Other Non-Current Liabilities | B33: 49848 | C33: 45888 | D33: 41549 | E33: ='Income Statement'!E8*Assumptions!$B$30 -> 44945.388 | F33: ='Income Statement'!F8*Assumptions!$B$30 -> 48091.565 | G33: ='Income Statement'!G8*Assumptions!$B$30 -> 51457.975
A34: Total Non-Current Liabilities | B34: =SUM(B32:B33) -> 145129 | C34: =SUM(C32:C33) -> 131638 | D34: =SUM(D32:D33) -> 119877 | E34: =SUM(E32:E33) -> 123273.39 | F34: =SUM(F32:F33) -> 126419.57 | G34: =SUM(G32:G33) -> 129785.97
A35: TOTAL LIABILITIES | B35: =B29+B34 -> 290437 | C35: =C29+C34 -> 308030 | D35: =D29+D34 -> 285508 | E35: =E29+E34 -> 298872.08 | F35: =F29+F34 -> 312440.48 | G35: =G29+G34 -> 327086.7
A37: Total Shareholders' Equity | B37: 62146 | C37: 56950 | D37: 73733 | E37: =D37+'Income Statement'!E28+'Cash Flow Statement'!E28+'Cash Flow Statement'!E29+'Cash Flow Statement'!E27+'Cash Flow Statement'!E8 -> 84444.551 | F37: =E37+'Income Statement'!F28+'Cash Flow Statement'!F28+'Cash Flow Statement'!F29+'Cash Flow Statement'!F27+'Cash Flow Statement'!F8 -> 98194.999 | G37: =F37+'Income Statement'!G28+'Cash Flow Statement'!G28+'Cash Flow Statement'!G29+'Cash Flow Statement'!G27+'Cash Flow Statement'!G8 -> 113536.1
A38: TOTAL LIABILITIES AND SHAREHOLDERS' EQUITY | B38: =B35+B37 -> 352583 | C38: =C35+C37 -> 364980 | D38: =D35+D37 -> 359241 | E38: =E35+E37 -> 383316.63 | F38: =F35+F37 -> 410635.48 | G38: =G35+G37 -> 440622.8
A40: Balance Check (Total Assets - Total Liab. & Equity) | B40: =ROUND(B20-B38,0) -> 0 | C40: =ROUND(C20-C38,0) -> 0 | D40: =ROUND(D20-D38,0) -> 0 | E40: =ROUND(E20-E38,0) -> 0 | F40: =ROUND(F20-F38,0) -> 0 | G40: =ROUND(G20-G38,0) -> 0

Sheet Cash Flow Statement
A1: Apple Inc. — Consolidated Statement of Cash Flows ($ in millions)
A2: FY2023A-FY2025A: actuals from 10-K/8-K filings | FY2026E-FY2028E: driven by Assumptions tab
B4: FY2023A | C4: FY2024A | D4: FY2025A | E4: FY2026E | F4: FY2027E | G4: FY2028E
A5: Operating Activities:
A6: Net Income | B6: 96995 | C6: 93736 | D6: 112010 | E6: ='Income Statement'!E28 -> 121945.83 | F6: ='Income Statement'!F28 -> 131693.94 | G6: ='Income Statement'!G28 -> 141777.01
A7: Depreciation and Amortization | B7: 11519 | C7: 11445 | D7: 11698 | E7: ='Income Statement'!E8*Assumptions!E35 -> 12584.709 | F7: ='Income Statement'!F8*Assumptions!F35 -> 13465.638 | G7: ='Income Statement'!G8*Assumptions!G35 -> 14408.233
A8: Share-Based Compensation Expense | B8: 10833 | C8: 11688 | D8: 12863 | E8: ='Income Statement'!E8*Assumptions!E36 -> 13483.616 | F8: ='Income Statement'!F8*Assumptions!F36 -> 14427.47 | G8: ='Income Statement'!G8*Assumptions!G36 -> 15437.392
A9: Other (non-cash) | B9: -2227 | C9: -2266 | D9: -89 | E9: 0 | F9: 0 | G9: 0
A10: Changes in operating assets and liabilities:
A11: Accounts Receivable, net | B11: -1688 | C11: -3788 | D11: -6682 | E11: =-('Balance Sheet'!E9-'Balance Sheet'!D9) -> -858.55627 | F11: =-('Balance Sheet'!F9-'Balance Sheet'!E9) -> -2844.4889 | G11: =-('Balance Sheet'!G9-'Balance Sheet'!F9) -> -3043.6032
A12: Vendor Non-Trade Receivables | B12: 1271 | C12: -1356 | D12: -347 | E12: =-('Balance Sheet'!E10-'Balance Sheet'!D10) -> -2776.3104 | F12: =-('Balance Sheet'!F10-'Balance Sheet'!E10) -> -2516.9417 | G12: =-('Balance Sheet'!G10-'Balance Sheet'!F10) -> -2693.1276
A13: Inventories | B13: -1618 | C13: -1046 | D13: 1400 | E13: =-('Balance Sheet'!E11-'Balance Sheet'!D11) -> -133.5201 | F13: =-('Balance Sheet'!F11-'Balance Sheet'!E11) -> -374.03182 | G13: =-('Balance Sheet'!G11-'Balance Sheet'!F11) -> -410.4121
A14: Other Current and Non-Current Assets | B14: -5684 | C14: -11731 | D14: -9197 | E14: =-(('Balance Sheet'!E12+'Balance Sheet'!E18)-('Balance Sheet'!D12+'Balance Sheet'!D18)) -> -7309.6618 | F14: =-(('Balance Sheet'!F12+'Balance Sheet'!F18)-('Balance Sheet'!E12+'Balance Sheet'!E18)) -> -7393.5163 | G14: =-(('Balance Sheet'!G12+'Balance Sheet'!G18)-('Balance Sheet'!F12+'Balance Sheet'!F18)) -> -7911.0625
A15: Accounts Payable | B15: -1889 | C15: 6020 | D15: 902 | E15: ='Balance Sheet'!E24-'Balance Sheet'!D24 -> 3609.0857 | F15: ='Balance Sheet'!F24-'Balance Sheet'!E24 -> 4696.1774 | G15: ='Balance Sheet'!G24-'Balance Sheet'!F24 -> 5152.9519
A16: Other Current and Non-Current Liabilities | B16: 3031 | C16: 15552 | D16: -11076 | E16: =(('Balance Sheet'!E25+'Balance Sheet'!E26+'Balance Sheet'!E33)-('Balance Sheet'!D25+'Balance Sheet'!D26+'Balance Sheet'!D33)) -> 9754.9942 | F16: =(('Balance Sheet'!F25+'Balance Sheet'!F26+'Balance Sheet'!F33)-('Balance Sheet'!E25+'Balance Sheet'!E26+'Balance Sheet'!E33)) -> 8872.2196 | G16: =(('Balance Sheet'!G25+'Balance Sheet'!G26+'Balance Sheet'!G33)-('Balance Sheet'!F25+'Balance Sheet'!F26+'Balance Sheet'!F33)) -> 9493.275
A17: Cash Generated by Operating Activities | B17: =SUM(B6:B16) -> 110543 | C17: =SUM(C6:C16) -> 118254 | D17: =SUM(D6:D16) -> 111482 | E17: =SUM(E6:E16) -> 150300.18 | F17: =SUM(F6:F16) -> 160026.47 | G17: =SUM(G6:G16) -> 172210.66
A19: Investing Activities:
A20: Purchases of Marketable Securities | B20: -29513 | C20: -48656 | D20: -24407 | E20: 0 | F20: 0 | G20: 0
A21: Proceeds from Maturities/Sales of Marketable Securities | B21: 45514 | C21: 62346 | D21: 53797 | E21: 0 | F21: 0 | G21: 0
A22: Other Investing | B22: -1337 | C22: -1308 | D22: -1480 | E22: 0 | F22: 0 | G22: 0
A23: Payments for Acquisition of Property, Plant & Equipment (Capex) | B23: -10959 | C23: -9447 | D23: -12715 | E23: =-('Income Statement'!E8*Assumptions!E34) -> -13483.616 | F23: =-('Income Statement'!F8*Assumptions!F34) -> -14427.47 | G23: =-('Income Statement'!G8*Assumptions!G34) -> -15437.392
A24: Cash Generated by/(Used in) Investing Activities | B24: =SUM(B20:B23) -> 3705 | C24: =SUM(C20:C23) -> 2935 | D24: =SUM(D20:D23) -> 15195 | E24: =SUM(E20:E23) -> -13483.616 | F24: =SUM(F20:F23) -> -14427.47 | G24: =SUM(G20:G23) -> -15437.392
A26: Financing Activities:
A27: Payments for Taxes on Net Share Settlement of Equity Awards | B27: -5431 | C27: -5441 | D27: -5960 | E27: =-(E8*Assumptions!E37) -> -6067.6274 | F27: =-(F8*Assumptions!F37) -> -6492.3613 | G27: =-(G8*Assumptions!G37) -> -6946.8266
A28: Payments for Dividends and Dividend Equivalents | B28: -15025 | C28: -15234 | D28: -15421 | E28: =D28*(1+Assumptions!$B$38) -> -16037.84 | F28: =E28*(1+Assumptions!$B$38) -> -16679.354 | G28: =F28*(1+Assumptions!$B$38) -> -17346.528
A29: Repurchases of Common Stock | B29: -77550 | C29: -94949 | D29: -90711 | E29: =-((E17+E24)*Assumptions!$B$39) -> -102612.43 | F29: =-((F17+F24)*Assumptions!$B$39) -> -109199.25 | G29: =-((G17+G24)*Assumptions!$B$39) -> -117579.95
A30: Debt Issuance/(Repayment) and Commercial Paper, net | B30: -9901 | C30: -5998 | D30: -8483 | E30: 0 | F30: 0 | G30: 0
A31: Other Financing | B31: -581 | C31: -361 | D31: -111 | E31: 0 | F31: 0 | G31: 0
A32: Cash Used in Financing Activities | B32: =SUM(B27:B31) -> -108488 | C32: =SUM(C27:C31) -> -121983 | D32: =SUM(D27:D31) -> -120686 | E32: =SUM(E27:E31) -> -124717.89 | F32: =SUM(F27:F31) -> -132370.96 | G32: =SUM(G27:G31) -> -141873.3
A34: Net Increase/(Decrease) in Cash | B34: =B17+B24+B32 -> 5760 | C34: =C17+C24+C32 -> -794 | D34: =D17+D24+D32 -> 5991 | E34: =E17+E24+E32 -> 12098.674 | F34: =F17+F24+F32 -> 13228.035 | G34: =G17+G24+G32 -> 14899.962
A35: Cash, Beginning of Period | B35: 24977 | C35: =B36 -> 30737 | D35: =C36 -> 29943 | E35: =D36 -> 35934 | F35: =E36 -> 48032.674 | G35: =F36 -> 61260.709
A36: Cash, End of Period | B36: =B35+B34 -> 30737 | C36: =C35+C34 -> 29943 | D36: =D35+D34 -> 35934 | E36: =E35+E34 -> 48032.674 | F36: =F35+F34 -> 61260.709 | G36: =G35+G34 -> 76160.671
A37: Note: ending cash here includes restricted cash equivalents per GAAP CFS presentation; ties to BS Cash line via the change in row 34.

Sheet Scenario Analysis
A1: Scenario Analysis — 'What If Revenue Drops 10%?'
A2: Live comparison: Base Case vs. Bear Case (-10% FY26E revenue shock) vs. Bull Case (+12% FY26E)
A4: Current Assumptions tab scenario selector is set to: | C4: =Assumptions!B4 -> Base
A6: FY2026E Revenue Growth Rate Applied | B6: Base | C6: Bear (-10% Rev Shock) | D6: Bull (Upside)
B7: =Assumptions!E8 -> 0.08 | C7: =Assumptions!E9 -> -0.1 | D7: =Assumptions!E10 -> 0.12
A9: FY2026E Income Statement Under Each Scenario
A10: Net Sales | B10: ='Income Statement'!$D$8*(1+Assumptions!$E$8) -> 449453.88 | C10: ='Income Statement'!$D$8*(1+Assumptions!$E$9) -> 374544.9 | D10: ='Income Statement'!$D$8*(1+Assumptions!$E$10) -> 466100.32
A11: Gross Margin | B11: =B10*Assumptions!$E$15 -> 212142.23 | C11: =C10*Assumptions!$E$15 -> 176785.19 | D11: =D10*Assumptions!$E$15 -> 219999.35
A12: Total Operating Expenses | B12: =B10*(Assumptions!$E$16+Assumptions!$E$17) -> 66519.174 | C12: =C10*(Assumptions!$E$16+Assumptions!$E$17) -> 55432.645 | D12: =D10*(Assumptions!$E$16+Assumptions!$E$17) -> 68982.847
A13: Operating Income | B13: =B11-B12 -> 145623.06 | C13: =C11-C12 -> 121352.55 | D13: =D11-D12 -> 151016.5
A14: Other Income/(Expense) | B14: =B10*Assumptions!$E$18 -> -449.45388 | C14: =C10*Assumptions!$E$18 -> -374.5449 | D14: =D10*Assumptions!$E$18 -> -466.10032
A15: Income Before Taxes | B15: =B13+B14 -> 145173.6 | C15: =C13+C14 -> 120978 | D15: =D13+D14 -> 150550.4
A16: Provision for Income Taxes | B16: =B15*Assumptions!$E$19 -> 23227.777 | C16: =C15*Assumptions!$E$19 -> 19356.48 | D16: =D15*Assumptions!$E$19 -> 24088.065
A17: Net Income | B17: =B15-B16 -> 121945.83 | C17: =C15-C16 -> 101621.52 | D17: =D15-D16 -> 126462.34
A18: Net Income vs. Base ($) | B18: =B17-$B$17 -> 0 | C18: =C17-$B$17 -> -20324.304 | D18: =D17-$B$17 -> 4516.5121
A19: Net Income vs. Base (%) | B19: =IFERROR((B17-$B$17)/$B$17,0) -> 0 | C19: =IFERROR((C17-$B$17)/$B$17,0) -> -0.16666667 | D19: =IFERROR((D17-$B$17)/$B$17,0) -> 0.037037037
A22: Takeaway: a 10-percentage-point revenue growth shock in FY26E (from +8% Base to -10% Bear) compresses FY26E Net Income by the figure shown above — operating expenses don't flex down with revenue in the short run (R&D/SG&A are modeled as % of revenue here, but in reality much of this is fixed in the near term), so margin compression amplifies the revenue hit to the bottom line.

Sheet Sensitivity Table
A1: FY2026E Sensitivity Analysis — Net Income & Free Cash Flow
A2: 2-way grid: Revenue Growth % (rows) x Gross Margin % (columns). All other assumptions held at Base Case.
A5: Net Income ($mm)
A6: Revenue Growth % \ Gross Margin % | B6: 0.45 | C6: 0.46 | D6: 0.47 | E6: 0.472 | F6: 0.48 | G6: 0.49
A7: -0.1 | B7: =((((('Income Statement'!$D$8*(1+$A7))*B$6)-(('Income Statement'!$D$8*(1+$A7))*(Assumptions!$E$16+Assumptions!$E$17)))+(('Income Statement'!$D$8*(1+$A7))*Assumptions!$E$18))-((((('Income Statement'!$D$8*(1+$A7))*B$6)-(('Income Statement'!$D$8*(1+$A7))*(Assumptions!$E$16+Assumptions!$E$17)))+(('Income Statement'!$D$8*(1+$A7))*Assumptions!$E$18))*Assumptions!$E$19)) -> 94699.933 | C7: =((((('Income Statement'!$D$8*(1+$A7))*C$6)-(('Income Statement'!$D$8*(1+$A7))*(Assumptions!$E$16+Assumptions!$E$17)))+(('Income Statement'!$D$8*(1+$A7))*Assumptions!$E$18))-((((('Income Statement'!$D$8*(1+$A7))*C$6)-(('Income Statement'!$D$8*(1+$A7))*(Assumptions!$E$16+Assumptions!$E$17)))+(('Income Statement'!$D$8*(1+$A7))*Assumptions!$E$18))*Assumptions!$E$19)) -> 97846.11 | D7: =((((('Income Statement'!$D$8*(1+$A7))*D$6)-(('Income Statement'!$D$8*(1+$A7))*(Assumptions!$E$16+Assumptions!$E$17)))+(('Income Statement'!$D$8*(1+$A7))*Assumptions!$E$18))-((((('Income Statement'!$D$8*(1+$A7))*D$6)-(('Income Statement'!$D$8*(1+$A7))*(Assumptions!$E$16+Assumptions!$E$17)))+(('Income Statement'!$D$8*(1+$A7))*Assumptions!$E$18))*Assumptions!$E$19)) -> 100992.29 | E7: =((((('Income Statement'!$D$8*(1+$A7))*E$6)-(('Income Statement'!$D$8*(1+$A7))*(Assumptions!$E$16+Assumptions!$E$17)))+(('Income Statement'!$D$8*(1+$A7))*Assumptions!$E$18))-((((('Income Statement'!$D$8*(1+$A7))*E$6)-(('Income Statement'!$D$8*(1+$A7))*(Assumptions!$E$16+Assumptions!$E$17)))+(('Income Statement'!$D$8*(1+$A7))*Assumptions!$E$18))*Assumptions!$E$19)) -> 101621.52 | F7: =((((('Income Statement'!$D$8*(1+$A7))*F$6)-(('Income Statement'!$D$8*(1+$A7))*(Assumptions!$E$16+Assumptions!$E$17)))+(('Income Statement'!$D$8*(1+$A7))*Assumptions!$E$18))-((((('Income Statement'!$D$8*(1+$A7))*F$6)-(('Income Statement'!$D$8*(1+$A7))*(Assumptions!$E$16+Assumptions!$E$17)))+(('Income Statement'!$D$8*(1+$A7))*Assumptions!$E$18))*Assumptions!$E$19)) -> 104138.46 | G7: =((((('Income Statement'!$D$8*(1+$A7))*G$6)-(('Income Statement'!$D$8*(1+$A7))*(Assumptions!$E$16+Assumptions!$E$17)))+(('Income Statement'!$D$8*(1+$A7))*Assumptions!$E$18))-((((('Income Statement'!$D$8*(1+$A7))*G$6)-(('Income Statement'!$D$8*(1+$A7))*(Assumptions!$E$16+Assumptions!$E$17)))+(('Income Statement'!$D$8*(1+$A7))*Assumptions!$E$18))*Assumptions!$E$19)) -> 107284.64
A8: -0.05 | B8: =((((('Income Statement'!$D$8*(1+$A8))*B$6)-(('Income Statement'!$D$8*(1+$A8))*(Assumptions!$E$16+Assumptions!$E$17)))+(('Income Statement'!$D$8*(1+$A8))*Assumptions!$E$18))-((((('Income Statement'!$D$8*(1+$A8))*B$6)-(('Income Statement'!$D$8*(1+$A8))*(Assumptions!$E$16+Assumptions!$E$17)))+(('Income Statement'!$D$8*(1+$A8))*Assumptions!$E$18))*Assumptions!$E$19)) -> 99961.04 | C8: =((((('Income Statement'!$D$8*(1+$A8))*C$6)-(('Income Statement'!$D$8*(1+$A8))*(Assumptions!$E$16+Assumptions!$E$17)))+(('Income Statement'!$D$8*(1+$A8))*Assumptions!$E$18))-((((('Income Statement'!$D$8*(1+$A8))*C$6)-(('Income Statement'!$D$8*(1+$A8))*(Assumptions!$E$16+Assumptions!$E$17)))+(('Income Statement'!$D$8*(1+$A8))*Assumptions!$E$18))*Assumptions!$E$19)) -> 103282 | D8: =((((('Income Statement'!$D$8*(1+$A8))*D$6)-(('Income Statement'!$D$8*(1+$A8))*(Assumptions!$E$16+Assumptions!$E$17)))+(('Income Statement'!$D$8*(1+$A8))*Assumptions!$E$18))-((((('Income Statement'!$D$8*(1+$A8))*D$6)-(('Income Statement'!$D$8*(1+$A8))*(Assumptions!$E$16+Assumptions!$E$17)))+(('Income Statement'!$D$8*(1+$A8))*Assumptions!$E$18))*Assumptions!$E$19)) -> 106602.97 | E8: =((((('Income Statement'!$D$8*(1+$A8))*E$6)-(('Income Statement'!$D$8*(1+$A8))*(Assumptions!$E$16+Assumptions!$E$17)))+(('Income Statement'!$D$8*(1+$A8))*Assumptions!$E$18))-((((('Income Statement'!$D$8*(1+$A8))*E$6)-(('Income Statement'!$D$8*(1+$A8))*(Assumptions!$E$16+Assumptions!$E$17)))+(('Income Statement'!$D$8*(1+$A8))*Assumptions!$E$18))*Assumptions!$E$19)) -> 107267.16 | F8: =((((('Income Statement'!$D$8*(1+$A8))*F$6)-(('Income Statement'!$D$8*(1+$A8))*(Assumptions!$E$16+Assumptions!$E$17)))+(('Income Statement'!$D$8*(1+$A8))*Assumptions!$E$18))-((((('Income Statement'!$D$8*(1+$A8))*F$6)-(('Income Statement'!$D$8*(1+$A8))*(Assumptions!$E$16+Assumptions!$E$17)))+(('Income Statement'!$D$8*(1+$A8))*Assumptions!$E$18))*Assumptions!$E$19)) -> 109923.93 | G8: =((((('Income Statement'!$D$8*(1+$A8))*G$6)-(('Income Statement'!$D$8*(1+$A8))*(Assumptions!$E$16+Assumptions!$E$17)))+(('Income Statement'!$D$8*(1+$A8))*Assumptions!$E$18))-((((('Income Statement'!$D$8*(1+$A8))*G$6)-(('Income Statement'!$D$8*(1+$A8))*(Assumptions!$E$16+Assumptions!$E$17)))+(('Income Statement'!$D$8*(1+$A8))*Assumptions!$E$18))*Assumptions!$E$19)) -> 113244.9
A9: 0 | B9: =((((('Income Statement'!$D$8*(1+$A9))*B$6)-(('Income Statement'!$D$8*(1+$A9))*(Assumptions!$E$16+Assumptions!$E$17)))+(('Income Statement'!$D$8*(1+$A9))*Assumptions!$E$18))-((((('Income Statement'!$D$8*(1+$A9))*B$6)-(('Income Statement'!$D$8*(1+$A9))*(Assumptions!$E$16+Assumptions!$E$17)))+(('Income Statement'!$D$8*(1+$A9))*Assumptions!$E$18))*Assumptions!$E$19)) -> 105222.15 | C9: =((((('Income Statement'!$D$8*(1+$A9))*C$6)-(('Income Statement'!$D$8*(1+$A9))*(Assumptions!$E$16+Assumptions!$E$17)))+(('Income Statement'!$D$8*(1+$A9))*Assumptions!$E$18))-((((('Income Statement'!$D$8*(1+$A9))*C$6)-(('Income Statement'!$D$8*(1+$A9))*(Assumptions!$E$16+Assumptions!$E$17)))+(('Income Statement'!$D$8*(1+$A9))*Assumptions!$E$18))*Assumptions!$E$19)) -> 108717.9 | D9: =((((('Income Statement'!$D$8*(1+$A9))*D$6)-(('Income Statement'!$D$8*(1+$A9))*(Assumptions!$E$16+Assumptions!$E$17)))+(('Income Statement'!$D$8*(1+$A9))*Assumptions!$E$18))-((((('Income Statement'!$D$8*(1+$A9))*D$6)-(('Income Statement'!$D$8*(1+$A9))*(Assumptions!$E$16+Assumptions!$E$17)))+(('Income Statement'!$D$8*(1+$A9))*Assumptions!$E$18))*Assumptions!$E$19)) -> 112213.65 | E9: =((((('Income Statement'!$D$8*(1+$A9))*E$6)-(('Income Statement'!$D$8*(1+$A9))*(Assumptions!$E$16+Assumptions!$E$17)))+(('Income Statement'!$D$8*(1+$A9))*Assumptions!$E$18))-((((('Income Statement'!$D$8*(1+$A9))*E$6)-(('Income Statement'!$D$8*(1+$A9))*(Assumptions!$E$16+Assumptions!$E$17)))+(('Income Statement'!$D$8*(1+$A9))*Assumptions!$E$18))*Assumptions!$E$19)) -> 112912.8 | F9: =((((('Income Statement'!$D$8*(1+$A9))*F$6)-(('Income Statement'!$D$8*(1+$A9))*(Assumptions!$E$16+Assumptions!$E$17)))+(('Income Statement'!$D$8*(1+$A9))*Assumptions!$E$18))-((((('Income Statement'!$D$8*(1+$A9))*F$6)-(('Income Statement'!$D$8*(1+$A9))*(Assumptions!$E$16+Assumptions!$E$17)))+(('Income Statement'!$D$8*(1+$A9))*Assumptions!$E$18))*Assumptions!$E$19)) -> 115709.4 | G9: =((((('Income Statement'!$D$8*(1+$A9))*G$6)-(('Income Statement'!$D$8*(1+$A9))*(Assumptions!$E$16+Assumptions!$E$17)))+(('Income Statement'!$D$8*(1+$A9))*Assumptions!$E$18))-((((('Income Statement'!$D$8*(1+$A9))*G$6)-(('Income Statement'!$D$8*(1+$A9))*(Assumptions!$E$16+Assumptions!$E$17)))+(('Income Statement'!$D$8*(1+$A9))*Assumptions!$E$18))*Assumptions!$E$19)) -> 119205.16
A10: 0.08 | B10: =((((('Income Statement'!$D$8*(1+$A10))*B$6)-(('Income Statement'!$D$8*(1+$A10))*(Assumptions!$E$16+Assumptions!$E$17)))+(('Income Statement'!$D$8*(1+$A10))*Assumptions!$E$18))-((((('Income Statement'!$D$8*(1+$A10))*B$6)-(('Income Statement'!$D$8*(1+$A10))*(Assumptions!$E$16+Assumptions!$E$17)))+(('Income Statement'!$D$8*(1+$A10))*Assumptions!$E$18))*Assumptions!$E$19)) -> 113639.92 | C10: =((((('Income Statement'!$D$8*(1+$A10))*C$6)-(('Income Statement'!$D$8*(1+$A10))*(Assumptions!$E$16+Assumptions!$E$17)))+(('Income Statement'!$D$8*(1+$A10))*Assumptions!$E$18))-((((('Income Statement'!$D$8*(1+$A10))*C$6)-(('Income Statement'!$D$8*(1+$A10))*(Assumptions!$E$16+Assumptions!$E$17)))+(('Income Statement'!$D$8*(1+$A10))*Assumptions!$E$18))*Assumptions!$E$19)) -> 117415.33 | D10: =((((('Income Statement'!$D$8*(1+$A10))*D$6)-(('Income Statement'!$D$8*(1+$A10))*(Assumptions!$E$16+Assumptions!$E$17)))+(('Income Statement'!$D$8*(1+$A10))*Assumptions!$E$18))-((((('Income Statement'!$D$8*(1+$A10))*D$6)-(('Income Statement'!$D$8*(1+$A10))*(Assumptions!$E$16+Assumptions!$E$17)))+(('Income Statement'!$D$8*(1+$A10))*Assumptions!$E$18))*Assumptions!$E$19)) -> 121190.74 | E10: =((((('Income Statement'!$D$8*(1+$A10))*E$6)-(('Income Statement'!$D$8*(1+$A10))*(Assumptions!$E$16+Assumptions!$E$17)))+(('Income Statement'!$D$8*(1+$A10))*Assumptions!$E$18))-((((('Income Statement'!$D$8*(1+$A10))*E$6)-(('Income Statement'!$D$8*(1+$A10))*(Assumptions!$E$16+Assumptions!$E$17)))+(('Income Statement'!$D$8*(1+$A10))*Assumptions!$E$18))*Assumptions!$E$19)) -> 121945.83 | F10: =((((('Income Statement'!$D$8*(1+$A10))*F$6)-(('Income Statement'!$D$8*(1+$A10))*(Assumptions!$E$16+Assumptions!$E$17)))+(('Income Statement'!$D$8*(1+$A10))*Assumptions!$E$18))-((((('Income Statement'!$D$8*(1+$A10))*F$6)-(('Income Statement'!$D$8*(1+$A10))*(Assumptions!$E$16+Assumptions!$E$17)))+(('Income Statement'!$D$8*(1+$A10))*Assumptions!$E$18))*Assumptions!$E$19)) -> 124966.16 | G10: =((((('Income Statement'!$D$8*(1+$A10))*G$6)-(('Income Statement'!$D$8*(1+$A10))*(Assumptions!$E$16+Assumptions!$E$17)))+(('Income Statement'!$D$8*(1+$A10))*Assumptions!$E$18))-((((('Income Statement'!$D$8*(1+$A10))*G$6)-(('Income Statement'!$D$8*(1+$A10))*(Assumptions!$E$16+Assumptions!$E$17)))+(('Income Statement'!$D$8*(1+$A10))*Assumptions!$E$18))*Assumptions!$E$19)) -> 128741.57
A11: 0.12 | B11: =((((('Income Statement'!$D$8*(1+$A11))*B$6)-(('Income Statement'!$D$8*(1+$A11))*(Assumptions!$E$16+Assumptions!$E$17)))+(('Income Statement'!$D$8*(1+$A11))*Assumptions!$E$18))-((((('Income Statement'!$D$8*(1+$A11))*B$6)-(('Income Statement'!$D$8*(1+$A11))*(Assumptions!$E$16+Assumptions!$E$17)))+(('Income Statement'!$D$8*(1+$A11))*Assumptions!$E$18))*Assumptions!$E$19)) -> 117848.8 | C11: =((((('Income Statement'!$D$8*(1+$A11))*C$6)-(('Income Statement'!$D$8*(1+$A11))*(Assumptions!$E$16+Assumptions!$E$17)))+(('Income Statement'!$D$8*(1+$A11))*Assumptions!$E$18))-((((('Income Statement'!$D$8*(1+$A11))*C$6)-(('Income Statement'!$D$8*(1+$A11))*(Assumptions!$E$16+Assumptions!$E$17)))+(('Income Statement'!$D$8*(1+$A11))*Assumptions!$E$18))*Assumptions!$E$19)) -> 121764.05 | D11: =((((('Income Statement'!$D$8*(1+$A11))*D$6)-(('Income Statement'!$D$8*(1+$A11))*(Assumptions!$E$16+Assumptions!$E$17)))+(('Income Statement'!$D$8*(1+$A11))*Assumptions!$E$18))-((((('Income Statement'!$D$8*(1+$A11))*D$6)-(('Income Statement'!$D$8*(1+$A11))*(Assumptions!$E$16+Assumptions!$E$17)))+(('Income Statement'!$D$8*(1+$A11))*Assumptions!$E$18))*Assumptions!$E$19)) -> 125679.29 | E11: =((((('Income Statement'!$D$8*(1+$A11))*E$6)-(('Income Statement'!$D$8*(1+$A11))*(Assumptions!$E$16+Assumptions!$E$17)))+(('Income Statement'!$D$8*(1+$A11))*Assumptions!$E$18))-((((('Income Statement'!$D$8*(1+$A11))*E$6)-(('Income Statement'!$D$8*(1+$A11))*(Assumptions!$E$16+Assumptions!$E$17)))+(('Income Statement'!$D$8*(1+$A11))*Assumptions!$E$18))*Assumptions!$E$19)) -> 126462.34 | F11: =((((('Income Statement'!$D$8*(1+$A11))*F$6)-(('Income Statement'!$D$8*(1+$A11))*(Assumptions!$E$16+Assumptions!$E$17)))+(('Income Statement'!$D$8*(1+$A11))*Assumptions!$E$18))-((((('Income Statement'!$D$8*(1+$A11))*F$6)-(('Income Statement'!$D$8*(1+$A11))*(Assumptions!$E$16+Assumptions!$E$17)))+(('Income Statement'!$D$8*(1+$A11))*Assumptions!$E$18))*Assumptions!$E$19)) -> 129594.53 | G11: =((((('Income Statement'!$D$8*(1+$A11))*G$6)-(('Income Statement'!$D$8*(1+$A11))*(Assumptions!$E$16+Assumptions!$E$17)))+(('Income Statement'!$D$8*(1+$A11))*Assumptions!$E$18))-((((('Income Statement'!$D$8*(1+$A11))*G$6)-(('Income Statement'!$D$8*(1+$A11))*(Assumptions!$E$16+Assumptions!$E$17)))+(('Income Statement'!$D$8*(1+$A11))*Assumptions!$E$18))*Assumptions!$E$19)) -> 133509.78
A12: 0.15 | B12: =((((('Income Statement'!$D$8*(1+$A12))*B$6)-(('Income Statement'!$D$8*(1+$A12))*(Assumptions!$E$16+Assumptions!$E$17)))+(('Income Statement'!$D$8*(1+$A12))*Assumptions!$E$18))-((((('Income Statement'!$D$8*(1+$A12))*B$6)-(('Income Statement'!$D$8*(1+$A12))*(Assumptions!$E$16+Assumptions!$E$17)))+(('Income Statement'!$D$8*(1+$A12))*Assumptions!$E$18))*Assumptions!$E$19)) -> 121005.47 | C12: =((((('Income Statement'!$D$8*(1+$A12))*C$6)-(('Income Statement'!$D$8*(1+$A12))*(Assumptions!$E$16+Assumptions!$E$17)))+(('Income Statement'!$D$8*(1+$A12))*Assumptions!$E$18))-((((('Income Statement'!$D$8*(1+$A12))*C$6)-(('Income Statement'!$D$8*(1+$A12))*(Assumptions!$E$16+Assumptions!$E$17)))+(('Income Statement'!$D$8*(1+$A12))*Assumptions!$E$18))*Assumptions!$E$19)) -> 125025.58 | D12: =((((('Income Statement'!$D$8*(1+$A12))*D$6)-(('Income Statement'!$D$8*(1+$A12))*(Assumptions!$E$16+Assumptions!$E$17)))+(('Income Statement'!$D$8*(1+$A12))*Assumptions!$E$18))-((((('Income Statement'!$D$8*(1+$A12))*D$6)-(('Income Statement'!$D$8*(1+$A12))*(Assumptions!$E$16+Assumptions!$E$17)))+(('Income Statement'!$D$8*(1+$A12))*Assumptions!$E$18))*Assumptions!$E$19)) -> 129045.7 | E12: =((((('Income Statement'!$D$8*(1+$A12))*E$6)-(('Income Statement'!$D$8*(1+$A12))*(Assumptions!$E$16+Assumptions!$E$17)))+(('Income Statement'!$D$8*(1+$A12))*Assumptions!$E$18))-((((('Income Statement'!$D$8*(1+$A12))*E$6)-(('Income Statement'!$D$8*(1+$A12))*(Assumptions!$E$16+Assumptions!$E$17)))+(('Income Statement'!$D$8*(1+$A12))*Assumptions!$E$18))*Assumptions!$E$19)) -> 129849.72 | F12: =((((('Income Statement'!$D$8*(1+$A12))*F$6)-(('Income Statement'!$D$8*(1+$A12))*(Assumptions!$E$16+Assumptions!$E$17)))+(('Income Statement'!$D$8*(1+$A12))*Assumptions!$E$18))-((((('Income Statement'!$D$8*(1+$A12))*F$6)-(('Income Statement'!$D$8*(1+$A12))*(Assumptions!$E$16+Assumptions!$E$17)))+(('Income Statement'!$D$8*(1+$A12))*Assumptions!$E$18))*Assumptions!$E$19)) -> 133065.82 | G12: =((((('Income Statement'!$D$8*(1+$A12))*G$6)-(('Income Statement'!$D$8*(1+$A12))*(Assumptions!$E$16+Assumptions!$E$17)))+(('Income Statement'!$D$8*(1+$A12))*Assumptions!$E$18))-((((('Income Statement'!$D$8*(1+$A12))*G$6)-(('Income Statement'!$D$8*(1+$A12))*(Assumptions!$E$16+Assumptions!$E$17)))+(('Income Statement'!$D$8*(1+$A12))*Assumptions!$E$18))*Assumptions!$E$19)) -> 137085.93
A15: Free Cash Flow ($mm) = Cash from Operations - Capex
A16: Revenue Growth % \ Gross Margin % | B16: 0.45 | C16: 0.46 | D16: 0.47 | E16: 0.472 | F16: 0.48 | G16: 0.49
A17: -0.1 | B17: =(((((('Income Statement'!$D$8*(1+$A17))*B$16)-(('Income Statement'!$D$8*(1+$A17))*(Assumptions!$E$16+Assumptions!$E$17)))+(('Income Statement'!$D$8*(1+$A17))*Assumptions!$E$18))-((((('Income Statement'!$D$8*(1+$A17))*B$16)-(('Income Statement'!$D$8*(1+$A17))*(Assumptions!$E$16+Assumptions!$E$17)))+(('Income Statement'!$D$8*(1+$A17))*Assumptions!$E$18))*Assumptions!$E$19))+(('Income Statement'!$D$8*(1+$A17))*Assumptions!$E$35)+(('Income Statement'!$D$8*(1+$A17))*Assumptions!$E$36)+(-((('Income Statement'!$D$8*(1+$A17))/365*Assumptions!$B$22)-'Balance Sheet'!$D$9))+(-((('Income Statement'!$D$8*(1+$A17))*Assumptions!$B$25)-'Balance Sheet'!$D$10))+(-(((('Income Statement'!$D$8*(1+$A17))*(1-B$16))/365*Assumptions!$B$23)-'Balance Sheet'!$D$11))+(-((('Income Statement'!$D$8*(1+$A17))*(Assumptions!$B$26+Assumptions!$B$27))-('Balance Sheet'!$D$12+'Balance Sheet'!$D$18)))+(((('Income Statement'!$D$8*(1+$A17))*(1-B$16))/365*Assumptions!$B$24)-'Balance Sheet'!$D$24)+((('Income Statement'!$D$8*(1+$A17))*(Assumptions!$B$28+Assumptions!$B$29+Assumptions!$B$30))-('Balance Sheet'!$D$25+'Balance Sheet'!$D$26+'Balance Sheet'!$D$33)))-(('Income Statement'!$D$8*(1+$A17))*Assumptions!$E$34) -> 107796.05 | C17: =(((((('Income Statement'!$D$8*(1+$A17))*C$16)-(('Income Statement'!$D$8*(1+$A17))*(Assumptions!$E$16+Assumptions!$E$17)))+(('Income Statement'!$D$8*(1+$A17))*Assumptions!$E$18))-((((('Income Statement'!$D$8*(1+$A17))*C$16)-(('Income Statement'!$D$8*(1+$A17))*(Assumptions!$E$16+Assumptions!$E$17)))+(('Income Statement'!$D$8*(1+$A17))*Assumptions!$E$18))*Assumptions!$E$19))+(('Income Statement'!$D$8*(1+$A17))*Assumptions!$E$35)+(('Income Statement'!$D$8*(1+$A17))*Assumptions!$E$36)+(-((('Income Statement'!$D$8*(1+$A17))/365*Assumptions!$B$22)-'Balance Sheet'!$D$9))+(-((('Income Statement'!$D$8*(1+$A17))*Assumptions!$B$25)-'Balance Sheet'!$D$10))+(-(((('Income Statement'!$D$8*(1+$A17))*(1-C$16))/365*Assumptions!$B$23)-'Balance Sheet'!$D$11))+(-((('Income Statement'!$D$8*(1+$A17))*(Assumptions!$B$26+Assumptions!$B$27))-('Balance Sheet'!$D$12+'Balance Sheet'!$D$18)))+(((('Income Statement'!$D$8*(1+$A17))*(1-C$16))/365*Assumptions!$B$24)-'Balance Sheet'!$D$24)+((('Income Statement'!$D$8*(1+$A17))*(Assumptions!$B$28+Assumptions!$B$29+Assumptions!$B$30))-('Balance Sheet'!$D$25+'Balance Sheet'!$D$26+'Balance Sheet'!$D$33)))-(('Income Statement'!$D$8*(1+$A17))*Assumptions!$E$34) -> 109875.03 | D17: =(((((('Income Statement'!$D$8*(1+$A17))*D$16)-(('Income Statement'!$D$8*(1+$A17))*(Assumptions!$E$16+Assumptions!$E$17)))+(('Income Statement'!$D$8*(1+$A17))*Assumptions!$E$18))-((((('Income Statement'!$D$8*(1+$A17))*D$16)-(('Income Statement'!$D$8*(1+$A17))*(Assumptions!$E$16+Assumptions!$E$17)))+(('Income Statement'!$D$8*(1+$A17))*Assumptions!$E$18))*Assumptions!$E$19))+(('Income Statement'!$D$8*(1+$A17))*Assumptions!$E$35)+(('Income Statement'!$D$8*(1+$A17))*Assumptions!$E$36)+(-((('Income Statement'!$D$8*(1+$A17))/365*Assumptions!$B$22)-'Balance Sheet'!$D$9))+(-((('Income Statement'!$D$8*(1+$A17))*Assumptions!$B$25)-'Balance Sheet'!$D$10))+(-(((('Income Statement'!$D$8*(1+$A17))*(1-D$16))/365*Assumptions!$B$23)-'Balance Sheet'!$D$11))+(-((('Income Statement'!$D$8*(1+$A17))*(Assumptions!$B$26+Assumptions!$B$27))-('Balance Sheet'!$D$12+'Balance Sheet'!$D$18)))+(((('Income Statement'!$D$8*(1+$A17))*(1-D$16))/365*Assumptions!$B$24)-'Balance Sheet'!$D$24)+((('Income Statement'!$D$8*(1+$A17))*(Assumptions!$B$28+Assumptions!$B$29+Assumptions!$B$30))-('Balance Sheet'!$D$25+'Balance Sheet'!$D$26+'Balance Sheet'!$D$33)))-(('Income Statement'!$D$8*(1+$A17))*Assumptions!$E$34) -> 111954.01 | E17: =(((((('Income Statement'!$D$8*(1+$A17))*E$16)-(('Income Statement'!$D$8*(1+$A17))*(Assumptions!$E$16+Assumptions!$E$17)))+(('Income Statement'!$D$8*(1+$A17))*Assumptions!$E$18))-((((('Income Statement'!$D$8*(1+$A17))*E$16)-(('Income Statement'!$D$8*(1+$A17))*(Assumptions!$E$16+Assumptions!$E$17)))+(('Income Statement'!$D$8*(1+$A17))*Assumptions!$E$18))*Assumptions!$E$19))+(('Income Statement'!$D$8*(1+$A17))*Assumptions!$E$35)+(('Income Statement'!$D$8*(1+$A17))*Assumptions!$E$36)+(-((('Income Statement'!$D$8*(1+$A17))/365*Assumptions!$B$22)-'Balance Sheet'!$D$9))+(-((('Income Statement'!$D$8*(1+$A17))*Assumptions!$B$25)-'Balance Sheet'!$D$10))+(-(((('Income Statement'!$D$8*(1+$A17))*(1-E$16))/365*Assumptions!$B$23)-'Balance Sheet'!$D$11))+(-((('Income Statement'!$D$8*(1+$A17))*(Assumptions!$B$26+Assumptions!$B$27))-('Balance Sheet'!$D$12+'Balance Sheet'!$D$18)))+(((('Income Statement'!$D$8*(1+$A17))*(1-E$16))/365*Assumptions!$B$24)-'Balance Sheet'!$D$24)+((('Income Statement'!$D$8*(1+$A17))*(Assumptions!$B$28+Assumptions!$B$29+Assumptions!$B$30))-('Balance Sheet'!$D$25+'Balance Sheet'!$D$26+'Balance Sheet'!$D$33)))-(('Income Statement'!$D$8*(1+$A17))*Assumptions!$E$34) -> 112369.81 | F17: =(((((('Income Statement'!$D$8*(1+$A17))*F$16)-(('Income Statement'!$D$8*(1+$A17))*(Assumptions!$E$16+Assumptions!$E$17)))+(('Income Statement'!$D$8*(1+$A17))*Assumptions!$E$18))-((((('Income Statement'!$D$8*(1+$A17))*F$16)-(('Income Statement'!$D$8*(1+$A17))*(Assumptions!$E$16+Assumptions!$E$17)))+(('Income Statement'!$D$8*(1+$A17))*Assumptions!$E$18))*Assumptions!$E$19))+(('Income Statement'!$D$8*(1+$A17))*Assumptions!$E$35)+(('Income Statement'!$D$8*(1+$A17))*Assumptions!$E$36)+(-((('Income Statement'!$D$8*(1+$A17))/365*Assumptions!$B$22)-'Balance Sheet'!$D$9))+(-((('Income Statement'!$D$8*(1+$A17))*Assumptions!$B$25)-'Balance Sheet'!$D$10))+(-(((('Income Statement'!$D$8*(1+$A17))*(1-F$16))/365*Assumptions!$B$23)-'Balance Sheet'!$D$11))+(-((('Income Statement'!$D$8*(1+$A17))*(Assumptions!$B$26+Assumptions!$B$27))-('Balance Sheet'!$D$12+'Balance Sheet'!$D$18)))+(((('Income Statement'!$D$8*(1+$A17))*(1-F$16))/365*Assumptions!$B$24)-'Balance Sheet'!$D$24)+((('Income Statement'!$D$8*(1+$A17))*(Assumptions!$B$28+Assumptions!$B$29+Assumptions!$B$30))-('Balance Sheet'!$D$25+'Balance Sheet'!$D$26+'Balance Sheet'!$D$33)))-(('Income Statement'!$D$8*(1+$A17))*Assumptions!$E$34) -> 114032.99 | G17: =(((((('Income Statement'!$D$8*(1+$A17))*G$16)-(('Income Statement'!$D$8*(1+$A17))*(Assumptions!$E$16+Assumptions!$E$17)))+(('Income Statement'!$D$8*(1+$A17))*Assumptions!$E$18))-((((('Income Statement'!$D$8*(1+$A17))*G$16)-(('Income Statement'!$D$8*(1+$A17))*(Assumptions!$E$16+Assumptions!$E$17)))+(('Income Statement'!$D$8*(1+$A17))*Assumptions!$E$18))*Assumptions!$E$19))+(('Income Statement'!$D$8*(1+$A17))*Assumptions!$E$35)+(('Income Statement'!$D$8*(1+$A17))*Assumptions!$E$36)+(-((('Income Statement'!$D$8*(1+$A17))/365*Assumptions!$B$22)-'Balance Sheet'!$D$9))+(-((('Income Statement'!$D$8*(1+$A17))*Assumptions!$B$25)-'Balance Sheet'!$D$10))+(-(((('Income Statement'!$D$8*(1+$A17))*(1-G$16))/365*Assumptions!$B$23)-'Balance Sheet'!$D$11))+(-((('Income Statement'!$D$8*(1+$A17))*(Assumptions!$B$26+Assumptions!$B$27))-('Balance Sheet'!$D$12+'Balance Sheet'!$D$18)))+(((('Income Statement'!$D$8*(1+$A17))*(1-G$16))/365*Assumptions!$B$24)-'Balance Sheet'!$D$24)+((('Income Statement'!$D$8*(1+$A17))*(Assumptions!$B$28+Assumptions!$B$29+Assumptions!$B$30))-('Balance Sheet'!$D$25+'Balance Sheet'!$D$26+'Balance Sheet'!$D$33)))-(('Income Statement'!$D$8*(1+$A17))*Assumptions!$E$34) -> 116111.97
A18: -0.05 | B18: =(((((('Income Statement'!$D$8*(1+$A18))*B$16)-(('Income Statement'!$D$8*(1+$A18))*(Assumptions!$E$16+Assumptions!$E$17)))+(('Income Statement'!$D$8*(1+$A18))*Assumptions!$E$18))-((((('Income Statement'!$D$8*(1+$A18))*B$16)-(('Income Statement'!$D$8*(1+$A18))*(Assumptions!$E$16+Assumptions!$E$17)))+(('Income Statement'!$D$8*(1+$A18))*Assumptions!$E$18))*Assumptions!$E$19))+(('Income Statement'!$D$8*(1+$A18))*Assumptions!$E$35)+(('Income Statement'!$D$8*(1+$A18))*Assumptions!$E$36)+(-((('Income Statement'!$D$8*(1+$A18))/365*Assumptions!$B$22)-'Balance Sheet'!$D$9))+(-((('Income Statement'!$D$8*(1+$A18))*Assumptions!$B$25)-'Balance Sheet'!$D$10))+(-(((('Income Statement'!$D$8*(1+$A18))*(1-B$16))/365*Assumptions!$B$23)-'Balance Sheet'!$D$11))+(-((('Income Statement'!$D$8*(1+$A18))*(Assumptions!$B$26+Assumptions!$B$27))-('Balance Sheet'!$D$12+'Balance Sheet'!$D$18)))+(((('Income Statement'!$D$8*(1+$A18))*(1-B$16))/365*Assumptions!$B$24)-'Balance Sheet'!$D$24)+((('Income Statement'!$D$8*(1+$A18))*(Assumptions!$B$28+Assumptions!$B$29+Assumptions!$B$30))-('Balance Sheet'!$D$25+'Balance Sheet'!$D$26+'Balance Sheet'!$D$33)))-(('Income Statement'!$D$8*(1+$A18))*Assumptions!$E$34) -> 114332.72 | C18: =(((((('Income Statement'!$D$8*(1+$A18))*C$16)-(('Income Statement'!$D$8*(1+$A18))*(Assumptions!$E$16+Assumptions!$E$17)))+(('Income Statement'!$D$8*(1+$A18))*Assumptions!$E$18))-((((('Income Statement'!$D$8*(1+$A18))*C$16)-(('Income Statement'!$D$8*(1+$A18))*(Assumptions!$E$16+Assumptions!$E$17)))+(('Income Statement'!$D$8*(1+$A18))*Assumptions!$E$18))*Assumptions!$E$19))+(('Income Statement'!$D$8*(1+$A18))*Assumptions!$E$35)+(('Income Statement'!$D$8*(1+$A18))*Assumptions!$E$36)+(-((('Income Statement'!$D$8*(1+$A18))/365*Assumptions!$B$22)-'Balance Sheet'!$D$9))+(-((('Income Statement'!$D$8*(1+$A18))*Assumptions!$B$25)-'Balance Sheet'!$D$10))+(-(((('Income Statement'!$D$8*(1+$A18))*(1-C$16))/365*Assumptions!$B$23)-'Balance Sheet'!$D$11))+(-((('Income Statement'!$D$8*(1+$A18))*(Assumptions!$B$26+Assumptions!$B$27))-('Balance Sheet'!$D$12+'Balance Sheet'!$D$18)))+(((('Income Statement'!$D$8*(1+$A18))*(1-C$16))/365*Assumptions!$B$24)-'Balance Sheet'!$D$24)+((('Income Statement'!$D$8*(1+$A18))*(Assumptions!$B$28+Assumptions!$B$29+Assumptions!$B$30))-('Balance Sheet'!$D$25+'Balance Sheet'!$D$26+'Balance Sheet'!$D$33)))-(('Income Statement'!$D$8*(1+$A18))*Assumptions!$E$34) -> 116527.2 | D18: =(((((('Income Statement'!$D$8*(1+$A18))*D$16)-(('Income Statement'!$D$8*(1+$A18))*(Assumptions!$E$16+Assumptions!$E$17)))+(('Income Statement'!$D$8*(1+$A18))*Assumptions!$E$18))-((((('Income Statement'!$D$8*(1+$A18))*D$16)-(('Income Statement'!$D$8*(1+$A18))*(Assumptions!$E$16+Assumptions!$E$17)))+(('Income Statement'!$D$8*(1+$A18))*Assumptions!$E$18))*Assumptions!$E$19))+(('Income Statement'!$D$8*(1+$A18))*Assumptions!$E$35)+(('Income Statement'!$D$8*(1+$A18))*Assumptions!$E$36)+(-((('Income Statement'!$D$8*(1+$A18))/365*Assumptions!$B$22)-'Balance Sheet'!$D$9))+(-((('Income Statement'!$D$8*(1+$A18))*Assumptions!$B$25)-'Balance Sheet'!$D$10))+(-(((('Income Statement'!$D$8*(1+$A18))*(1-D$16))/365*Assumptions!$B$23)-'Balance Sheet'!$D$11))+(-((('Income Statement'!$D$8*(1+$A18))*(Assumptions!$B$26+Assumptions!$B$27))-('Balance Sheet'!$D$12+'Balance Sheet'!$D$18)))+(((('Income Statement'!$D$8*(1+$A18))*(1-D$16))/365*Assumptions!$B$24)-'Balance Sheet'!$D$24)+((('Income Statement'!$D$8*(1+$A18))*(Assumptions!$B$28+Assumptions!$B$29+Assumptions!$B$30))-('Balance Sheet'!$D$25+'Balance Sheet'!$D$26+'Balance Sheet'!$D$33)))-(('Income Statement'!$D$8*(1+$A18))*Assumptions!$E$34) -> 118721.68 | E18: =(((((('Income Statement'!$D$8*(1+$A18))*E$16)-(('Income Statement'!$D$8*(1+$A18))*(Assumptions!$E$16+Assumptions!$E$17)))+(('Income Statement'!$D$8*(1+$A18))*Assumptions!$E$18))-((((('Income Statement'!$D$8*(1+$A18))*E$16)-(('Income Statement'!$D$8*(1+$A18))*(Assumptions!$E$16+Assumptions!$E$17)))+(('Income Statement'!$D$8*(1+$A18))*Assumptions!$E$18))*Assumptions!$E$19))+(('Income Statement'!$D$8*(1+$A18))*Assumptions!$E$35)+(('Income Statement'!$D$8*(1+$A18))*Assumptions!$E$36)+(-((('Income Statement'!$D$8*(1+$A18))/365*Assumptions!$B$22)-'Balance Sheet'!$D$9))+(-((('Income Statement'!$D$8*(1+$A18))*Assumptions!$B$25)-'Balance Sheet'!$D$10))+(-(((('Income Statement'!$D$8*(1+$A18))*(1-E$16))/365*Assumptions!$B$23)-'Balance Sheet'!$D$11))+(-((('Income Statement'!$D$8*(1+$A18))*(Assumptions!$B$26+Assumptions!$B$27))-('Balance Sheet'!$D$12+'Balance Sheet'!$D$18)))+(((('Income Statement'!$D$8*(1+$A18))*(1-E$16))/365*Assumptions!$B$24)-'Balance Sheet'!$D$24)+((('Income Statement'!$D$8*(1+$A18))*(Assumptions!$B$28+Assumptions!$B$29+Assumptions!$B$30))-('Balance Sheet'!$D$25+'Balance Sheet'!$D$26+'Balance Sheet'!$D$33)))-(('Income Statement'!$D$8*(1+$A18))*Assumptions!$E$34) -> 119160.57 | F18: =(((((('Income Statement'!$D$8*(1+$A18))*F$16)-(('Income Statement'!$D$8*(1+$A18))*(Assumptions!$E$16+Assumptions!$E$17)))+(('Income Statement'!$D$8*(1+$A18))*Assumptions!$E$18))-((((('Income Statement'!$D$8*(1+$A18))*F$16)-(('Income Statement'!$D$8*(1+$A18))*(Assumptions!$E$16+Assumptions!$E$17)))+(('Income Statement'!$D$8*(1+$A18))*Assumptions!$E$18))*Assumptions!$E$19))+(('Income Statement'!$D$8*(1+$A18))*Assumptions!$E$35)+(('Income Statement'!$D$8*(1+$A18))*Assumptions!$E$36)+(-((('Income Statement'!$D$8*(1+$A18))/365*Assumptions!$B$22)-'Balance Sheet'!$D$9))+(-((('Income Statement'!$D$8*(1+$A18))*Assumptions!$B$25)-'Balance Sheet'!$D$10))+(-(((('Income Statement'!$D$8*(1+$A18))*(1-F$16))/365*Assumptions!$B$23)-'Balance Sheet'!$D$11))+(-((('Income Statement'!$D$8*(1+$A18))*(Assumptions!$B$26+Assumptions!$B$27))-('Balance Sheet'!$D$12+'Balance Sheet'!$D$18)))+(((('Income Statement'!$D$8*(1+$A18))*(1-F$16))/365*Assumptions!$B$24)-'Balance Sheet'!$D$24)+((('Income Statement'!$D$8*(1+$A18))*(Assumptions!$B$28+Assumptions!$B$29+Assumptions!$B$30))-('Balance Sheet'!$D$25+'Balance Sheet'!$D$26+'Balance Sheet'!$D$33)))-(('Income Statement'!$D$8*(1+$A18))*Assumptions!$E$34) -> 120916.16 | G18: =(((((('Income Statement'!$D$8*(1+$A18))*G$16)-(('Income Statement'!$D$8*(1+$A18))*(Assumptions!$E$16+Assumptions!$E$17)))+(('Income Statement'!$D$8*(1+$A18))*Assumptions!$E$18))-((((('Income Statement'!$D$8*(1+$A18))*G$16)-(('Income Statement'!$D$8*(1+$A18))*(Assumptions!$E$16+Assumptions!$E$17)))+(('Income Statement'!$D$8*(1+$A18))*Assumptions!$E$18))*Assumptions!$E$19))+(('Income Statement'!$D$8*(1+$A18))*Assumptions!$E$35)+(('Income Statement'!$D$8*(1+$A18))*Assumptions!$E$36)+(-((('Income Statement'!$D$8*(1+$A18))/365*Assumptions!$B$22)-'Balance Sheet'!$D$9))+(-((('Income Statement'!$D$8*(1+$A18))*Assumptions!$B$25)-'Balance Sheet'!$D$10))+(-(((('Income Statement'!$D$8*(1+$A18))*(1-G$16))/365*Assumptions!$B$23)-'Balance Sheet'!$D$11))+(-((('Income Statement'!$D$8*(1+$A18))*(Assumptions!$B$26+Assumptions!$B$27))-('Balance Sheet'!$D$12+'Balance Sheet'!$D$18)))+(((('Income Statement'!$D$8*(1+$A18))*(1-G$16))/365*Assumptions!$B$24)-'Balance Sheet'!$D$24)+((('Income Statement'!$D$8*(1+$A18))*(Assumptions!$B$28+Assumptions!$B$29+Assumptions!$B$30))-('Balance Sheet'!$D$25+'Balance Sheet'!$D$26+'Balance Sheet'!$D$33)))-(('Income Statement'!$D$8*(1+$A18))*Assumptions!$E$34) -> 123110.64
A19: 0 | B19: =(((((('Income Statement'!$D$8*(1+$A19))*B$16)-(('Income Statement'!$D$8*(1+$A19))*(Assumptions!$E$16+Assumptions!$E$17)))+(('Income Statement'!$D$8*(1+$A19))*Assumptions!$E$18))-((((('Income Statement'!$D$8*(1+$A19))*B$16)-(('Income Statement'!$D$8*(1+$A19))*(Assumptions!$E$16+Assumptions!$E$17)))+(('Income Statement'!$D$8*(1+$A19))*Assumptions!$E$18))*Assumptions!$E$19))+(('Income Statement'!$D$8*(1+$A19))*Assumptions!$E$35)+(('Income Statement'!$D$8*(1+$A19))*Assumptions!$E$36)+(-((('Income Statement'!$D$8*(1+$A19))/365*Assumptions!$B$22)-'Balance Sheet'!$D$9))+(-((('Income Statement'!$D$8*(1+$A19))*Assumptions!$B$25)-'Balance Sheet'!$D$10))+(-(((('Income Statement'!$D$8*(1+$A19))*(1-B$16))/365*Assumptions!$B$23)-'Balance Sheet'!$D$11))+(-((('Income Statement'!$D$8*(1+$A19))*(Assumptions!$B$26+Assumptions!$B$27))-('Balance Sheet'!$D$12+'Balance Sheet'!$D$18)))+(((('Income Statement'!$D$8*(1+$A19))*(1-B$16))/365*Assumptions!$B$24)-'Balance Sheet'!$D$24)+((('Income Statement'!$D$8*(1+$A19))*(Assumptions!$B$28+Assumptions!$B$29+Assumptions!$B$30))-('Balance Sheet'!$D$25+'Balance Sheet'!$D$26+'Balance Sheet'!$D$33)))-(('Income Statement'!$D$8*(1+$A19))*Assumptions!$E$34) -> 120869.39 | C19: =(((((('Income Statement'!$D$8*(1+$A19))*C$16)-(('Income Statement'!$D$8*(1+$A19))*(Assumptions!$E$16+Assumptions!$E$17)))+(('Income Statement'!$D$8*(1+$A19))*Assumptions!$E$18))-((((('Income Statement'!$D$8*(1+$A19))*C$16)-(('Income Statement'!$D$8*(1+$A19))*(Assumptions!$E$16+Assumptions!$E$17)))+(('Income Statement'!$D$8*(1+$A19))*Assumptions!$E$18))*Assumptions!$E$19))+(('Income Statement'!$D$8*(1+$A19))*Assumptions!$E$35)+(('Income Statement'!$D$8*(1+$A19))*Assumptions!$E$36)+(-((('Income Statement'!$D$8*(1+$A19))/365*Assumptions!$B$22)-'Balance Sheet'!$D$9))+(-((('Income Statement'!$D$8*(1+$A19))*Assumptions!$B$25)-'Balance Sheet'!$D$10))+(-(((('Income Statement'!$D$8*(1+$A19))*(1-C$16))/365*Assumptions!$B$23)-'Balance Sheet'!$D$11))+(-((('Income Statement'!$D$8*(1+$A19))*(Assumptions!$B$26+Assumptions!$B$27))-('Balance Sheet'!$D$12+'Balance Sheet'!$D$18)))+(((('Income Statement'!$D$8*(1+$A19))*(1-C$16))/365*Assumptions!$B$24)-'Balance Sheet'!$D$24)+((('Income Statement'!$D$8*(1+$A19))*(Assumptions!$B$28+Assumptions!$B$29+Assumptions!$B$30))-('Balance Sheet'!$D$25+'Balance Sheet'!$D$26+'Balance Sheet'!$D$33)))-(('Income Statement'!$D$8*(1+$A19))*Assumptions!$E$34) -> 123179.37 | D19: =(((((('Income Statement'!$D$8*(1+$A19))*D$16)-(('Income Statement'!$D$8*(1+$A19))*(Assumptions!$E$16+Assumptions!$E$17)))+(('Income Statement'!$D$8*(1+$A19))*Assumptions!$E$18))-((((('Income Statement'!$D$8*(1+$A19))*D$16)-(('Income Statement'!$D$8*(1+$A19))*(Assumptions!$E$16+Assumptions!$E$17)))+(('Income Statement'!$D$8*(1+$A19))*Assumptions!$E$18))*Assumptions!$E$19))+(('Income Statement'!$D$8*(1+$A19))*Assumptions!$E$35)+(('Income Statement'!$D$8*(1+$A19))*Assumptions!$E$36)+(-((('Income Statement'!$D$8*(1+$A19))/365*Assumptions!$B$22)-'Balance Sheet'!$D$9))+(-((('Income Statement'!$D$8*(1+$A19))*Assumptions!$B$25)-'Balance Sheet'!$D$10))+(-(((('Income Statement'!$D$8*(1+$A19))*(1-D$16))/365*Assumptions!$B$23)-'Balance Sheet'!$D$11))+(-((('Income Statement'!$D$8*(1+$A19))*(Assumptions!$B$26+Assumptions!$B$27))-('Balance Sheet'!$D$12+'Balance Sheet'!$D$18)))+(((('Income Statement'!$D$8*(1+$A19))*(1-D$16))/365*Assumptions!$B$24)-'Balance Sheet'!$D$24)+((('Income Statement'!$D$8*(1+$A19))*(Assumptions!$B$28+Assumptions!$B$29+Assumptions!$B$30))-('Balance Sheet'!$D$25+'Balance Sheet'!$D$26+'Balance Sheet'!$D$33)))-(('Income Statement'!$D$8*(1+$A19))*Assumptions!$E$34) -> 125489.34 | E19: =(((((('Income Statement'!$D$8*(1+$A19))*E$16)-(('Income Statement'!$D$8*(1+$A19))*(Assumptions!$E$16+Assumptions!$E$17)))+(('Income Statement'!$D$8*(1+$A19))*Assumptions!$E$18))-((((('Income Statement'!$D$8*(1+$A19))*E$16)-(('Income Statement'!$D$8*(1+$A19))*(Assumptions!$E$16+Assumptions!$E$17)))+(('Income Statement'!$D$8*(1+$A19))*Assumptions!$E$18))*Assumptions!$E$19))+(('Income Statement'!$D$8*(1+$A19))*Assumptions!$E$35)+(('Income Statement'!$D$8*(1+$A19))*Assumptions!$E$36)+(-((('Income Statement'!$D$8*(1+$A19))/365*Assumptions!$B$22)-'Balance Sheet'!$D$9))+(-((('Income Statement'!$D$8*(1+$A19))*Assumptions!$B$25)-'Balance Sheet'!$D$10))+(-(((('Income Statement'!$D$8*(1+$A19))*(1-E$16))/365*Assumptions!$B$23)-'Balance Sheet'!$D$11))+(-((('Income Statement'!$D$8*(1+$A19))*(Assumptions!$B$26+Assumptions!$B$27))-('Balance Sheet'!$D$12+'Balance Sheet'!$D$18)))+(((('Income Statement'!$D$8*(1+$A19))*(1-E$16))/365*Assumptions!$B$24)-'Balance Sheet'!$D$24)+((('Income Statement'!$D$8*(1+$A19))*(Assumptions!$B$28+Assumptions!$B$29+Assumptions!$B$30))-('Balance Sheet'!$D$25+'Balance Sheet'!$D$26+'Balance Sheet'!$D$33)))-(('Income Statement'!$D$8*(1+$A19))*Assumptions!$E$34) -> 125951.34 | F19: =(((((('Income Statement'!$D$8*(1+$A19))*F$16)-(('Income Statement'!$D$8*(1+$A19))*(Assumptions!$E$16+Assumptions!$E$17)))+(('Income Statement'!$D$8*(1+$A19))*Assumptions!$E$18))-((((('Income Statement'!$D$8*(1+$A19))*F$16)-(('Income Statement'!$D$8*(1+$A19))*(Assumptions!$E$16+Assumptions!$E$17)))+(('Income Statement'!$D$8*(1+$A19))*Assumptions!$E$18))*Assumptions!$E$19))+(('Income Statement'!$D$8*(1+$A19))*Assumptions!$E$35)+(('Income Statement'!$D$8*(1+$A19))*Assumptions!$E$36)+(-((('Income Statement'!$D$8*(1+$A19))/365*Assumptions!$B$22)-'Balance Sheet'!$D$9))+(-((('Income Statement'!$D$8*(1+$A19))*Assumptions!$B$25)-'Balance Sheet'!$D$10))+(-(((('Income Statement'!$D$8*(1+$A19))*(1-F$16))/365*Assumptions!$B$23)-'Balance Sheet'!$D$11))+(-((('Income Statement'!$D$8*(1+$A19))*(Assumptions!$B$26+Assumptions!$B$27))-('Balance Sheet'!$D$12+'Balance Sheet'!$D$18)))+(((('Income Statement'!$D$8*(1+$A19))*(1-F$16))/365*Assumptions!$B$24)-'Balance Sheet'!$D$24)+((('Income Statement'!$D$8*(1+$A19))*(Assumptions!$B$28+Assumptions!$B$29+Assumptions!$B$30))-('Balance Sheet'!$D$25+'Balance Sheet'!$D$26+'Balance Sheet'!$D$33)))-(('Income Statement'!$D$8*(1+$A19))*Assumptions!$E$34) -> 127799.32 | G19: =(((((('Income Statement'!$D$8*(1+$A19))*G$16)-(('Income Statement'!$D$8*(1+$A19))*(Assumptions!$E$16+Assumptions!$E$17)))+(('Income Statement'!$D$8*(1+$A19))*Assumptions!$E$18))-((((('Income Statement'!$D$8*(1+$A19))*G$16)-(('Income Statement'!$D$8*(1+$A19))*(Assumptions!$E$16+Assumptions!$E$17)))+(('Income Statement'!$D$8*(1+$A19))*Assumptions!$E$18))*Assumptions!$E$19))+(('Income Statement'!$D$8*(1+$A19))*Assumptions!$E$35)+(('Income Statement'!$D$8*(1+$A19))*Assumptions!$E$36)+(-((('Income Statement'!$D$8*(1+$A19))/365*Assumptions!$B$22)-'Balance Sheet'!$D$9))+(-((('Income Statement'!$D$8*(1+$A19))*Assumptions!$B$25)-'Balance Sheet'!$D$10))+(-(((('Income Statement'!$D$8*(1+$A19))*(1-G$16))/365*Assumptions!$B$23)-'Balance Sheet'!$D$11))+(-((('Income Statement'!$D$8*(1+$A19))*(Assumptions!$B$26+Assumptions!$B$27))-('Balance Sheet'!$D$12+'Balance Sheet'!$D$18)))+(((('Income Statement'!$D$8*(1+$A19))*(1-G$16))/365*Assumptions!$B$24)-'Balance Sheet'!$D$24)+((('Income Statement'!$D$8*(1+$A19))*(Assumptions!$B$28+Assumptions!$B$29+Assumptions!$B$30))-('Balance Sheet'!$D$25+'Balance Sheet'!$D$26+'Balance Sheet'!$D$33)))-(('Income Statement'!$D$8*(1+$A19))*Assumptions!$E$34) -> 130109.3
